<?xml version="1.0" encoding="utf-8"?>
<!-- =================================================================================== -->
<!--   Copyright 2024 PNDbotics, https://www.pndbotics.com/                              -->
<!-- =================================================================================== -->
<!-- This file contains the description of the adam standard robot. -->
<robot
  name="adam_standard">
  <link
    name="pelvis">
    <inertial>
      <origin
        xyz="-0.00120281  -0.00000119 -0.00802155"
        rpy="0 0 0" />
      <mass
        value="10.18730021" />
      <inertia
        ixx="0.06839529"
        ixy="-0.00000995"
        ixz="-0.00004308"
        iyy="0.03753230"
        iyz="-0.00000105"
        izz="0.07519708" />
    </inertial>
    <visual>
      <origin
        xyz="0 0 0"
        rpy="0 0 0" />
      <geometry>
        <mesh
          filename="../meshes/pelvis.STL" />
      </geometry>
      <material
        name="">
        <color
          rgba="1 1 1 1" />
      </material>
    </visual>
    <collision>
      <origin
        xyz="0.0 0.0 0"
        rpy="1.57 0 0" />
      <geometry>
        <cylinder length="0.2" radius="0.1"/>
      </geometry>
    </collision>
  </link>
  <link
    name="hipPitchLeft">
    <inertial>
      <origin
        xyz="-0.05818187 0.05889478 -0.00031205"
        rpy="0 0 0" />
      <mass
        value="2.15124786" />
      <inertia
        ixx="0.00385847"
        ixy="-0.00094455"
        ixz="0.00002598"
        iyy="0.00440973"
        iyz="0.00002828"
        izz="0.00508085" />
    </inertial>
    <visual>
      <origin
        xyz="0 0 0"
        rpy="0 0 0" />
      <geometry>
        <mesh
          filename="../meshes/hipPitchLeft.STL" />
      </geometry>
      <material
        name="">
        <color
          rgba="1 1 1 1" />
      </material>
    </visual>
  </link>
  <joint
    name="hipPitch_Left"
    type="revolute">
    <origin
      xyz="0 0.096192 -0.033241"
      rpy="-0.61087 0 0" />
    <parent
      link="pelvis" />
    <child
      link="hipPitchLeft" />
    <axis
      xyz="0 1 0" />
    <limit effort="230.0" lower="-2.09" upper="2.09" velocity="15.0"/>
  </joint>
  <link
    name="hipRollLeft">
    <inertial>
      <origin
        xyz="0.03995412 -0.00011618 -0.01102103"
        rpy="0 0 0" />
      <mass
        value="1.29421887" />
      <inertia
        ixx="0.00134168"
        ixy="-0.00000431"
        ixz="-0.00006007"
        iyy="0.00137070"
        iyz="-0.00001695"
        izz="0.00144577" />
    </inertial>
    <visual>
      <origin
        xyz="0 0 0"
        rpy="0 0 0" />
      <geometry>
        <mesh
          filename="../meshes/hipRollLeft.STL" />
      </geometry>
      <material
        name="">
        <color
          rgba="1 1 1 1" />
      </material>
    </visual>
  </link>
  <joint
    name="hipRoll_Left"
    type="revolute">
    <origin
      xyz="-0.0255 0.069 0"
      rpy="0.61087 0 0" />
    <parent
      link="hipPitchLeft" />
    <child
      link="hipRollLeft" />
    <axis
      xyz="1 0 0" />
    <limit effort="160.0" lower="-0.78" upper="1.57" velocity="8.0"/>
  </joint>
  <link
    name="thighLeft">
    <inertial>
      <origin
        xyz="0.00331195 -0.01112470 -0.13519832"
        rpy="0 0 0" />
      <mass
        value="6.64749717" />
      <inertia
        ixx="0.05688222"
        ixy="-0.00031813"
        ixz="-0.00156531"
        iyy="0.06217155"
        iyz="0.00531838"
        izz="0.01520394" />
    </inertial>
    <visual>
      <origin
        xyz="0 0 0"
        rpy="0 0 0" />
      <geometry>
        <mesh
          filename="../meshes/thighLeft.STL" />
      </geometry>
      <material
        name="">
        <color
          rgba="1 1 1 1" />
      </material>
    </visual>
  </link>
  <joint
    name="hipYaw_Left"
    type="revolute">
    <origin
      xyz="0.044 0 -0.0525"
      rpy="0 0 0" />
    <parent
      link="hipRollLeft" />
    <child
      link="thighLeft" />
    <axis
      xyz="0 0 1" />
    <limit effort="105" lower="-0.78" upper="0.78" velocity="8.0"/>
  </joint>
  <link
    name="shinLeft">
    <inertial>
      <origin
        xyz="-0.00080913 0.00097265 -0.14540818"
        rpy="0 0 0" />
      <mass
        value="2.19866469" />
      <inertia
        ixx="0.01932815"
        ixy="-0.00001127"
        ixz="0.00022012"
        iyy="0.01940985"
        iyz="0.00008606"
        izz="0.00136828" />
    </inertial>
    <visual>
      <origin
        xyz="0 0 0"
        rpy="0 0 0" />
      <geometry>
        <mesh
          filename="../meshes/shinLeft.STL" />
      </geometry>
      <material
        name="">
        <color
          rgba="1 1 1 1" />
      </material>
    </visual>
    <collision>
      <origin
        xyz="0.0 0.0 -0.2"
        rpy="0 0 0" />
      <geometry>
        <box size="0.08 0.06 0.3"/>
      </geometry>
    </collision>
  </link>
  <joint
    name="kneePitch_Left"
    type="revolute">
    <origin
      xyz="0 -0.0355 -0.369"
      rpy="0 0 0" />
    <parent
      link="thighLeft" />
    <child
      link="shinLeft" />
    <axis
      xyz="0 1 0" />
    <limit effort="230.0" lower="-0.09" upper="2.4" velocity="15.0"/>
  </joint>
  <link
    name="anklePitchLeft">
    <inertial>
      <origin
        xyz="0.00000000 0.00000000 0.00000000"
        rpy="0 0 0" />
      <mass
        value="0.03100000" />
      <inertia
        ixx="0.00000323"
        ixy="0.00000000"
        ixz="0.00000000"
        iyy="0.00000323"
        iyz="0.00000000"
        izz="0.00000210" />
    </inertial>
    <visual>
      <origin
        xyz="0 0 0"
        rpy="0 0 0" />
      <geometry>
        <mesh
          filename="../meshes/anklePitchLeft.STL" />
      </geometry>
      <material
        name="">
        <color
          rgba="1 1 1 1" />
      </material>
    </visual>
  </link>
  <joint
    name="anklePitch_Left"
    type="revolute">
    <origin
      xyz="0 0 -0.37"
      rpy="0 0 0" />
    <parent
      link="shinLeft" />
    <child
      link="anklePitchLeft" />
    <axis
      xyz="0 1 0" />
    <limit effort="40.0" lower="-1.0" upper="0.35" velocity="20.0"/>
  </joint>
  <link
    name="toeLeft">
    <inertial>
      <origin
        xyz="0.03700657 -0.00002063 -0.04198684"
        rpy="0 0 0" />
      <mass
        value="0.47580000" />
      <inertia
        ixx="0.00028492"
        ixy="0.00001326"
        ixz="-0.00012023"
        iyy="0.00152181"
        iyz="0.00000143"
        izz="0.00158187" />
    </inertial>
    <visual>
      <origin
        xyz="0 0 0"
        rpy="0 0 0" />
      <geometry>
        <mesh
          filename="../meshes/toeLeft.STL" />
      </geometry>
      <material
        name="">
        <color
          rgba="0.752941176470588 0.752941176470588 0.752941176470588 1" />
      </material>
    </visual>
    <collision name="toe_left">
      <origin rpy="0 0 0" xyz="0.047 0.0 -0.05"/>
      <geometry>
        <box size="0.24 0.1 0.03"/>
      </geometry>
    </collision>
  </link>
  <joint
    name="ankleRoll_Left"
    type="revolute">
    <origin
      xyz="0 0 0"
      rpy="0 0 0" />
    <parent
      link="anklePitchLeft" />
    <child
      link="toeLeft" />
    <axis
      xyz="1 0 0" />
    <limit effort="12.0" lower="-0.3491" upper="0.3491" velocity="20.0"/>
  </joint>
  <link
    name="leftFoot1">
    <inertial>
      <origin xyz="0 0 0" />
      <mass value="0.001" />
      <inertia 
        ixx="0.0001" 
        ixy="0" 
        ixz="0" 
        iyy="0.0001" 
        iyz="0" 
        izz="0.0001" />
    </inertial>
    <collision>
      <origin xyz="0 0 0" />
      <geometry>
        <sphere radius="0.001" />
      </geometry>
    </collision>
  </link>
  <joint
    name="leftFoot1"
    type="fixed">
    <origin xyz="0.167 0.05 -0.065" />
    <parent link="toeLeft" />
    <child link="leftFoot1" />
  </joint>
  <link
    name="leftFoot2">
    <inertial>
      <origin xyz="0 0 0" />
      <mass value="0.001" />
      <inertia 
        ixx="0.0001" 
        ixy="0" 
        ixz="0" 
        iyy="0.0001" 
        iyz="0" 
        izz="0.0001" />
    </inertial>
    <collision>
      <origin xyz="0 0 0" />
      <geometry>
        <sphere radius="0.001" />
      </geometry>
    </collision>
  </link>
  <joint
    name="leftFoot2"
    type="fixed">
    <origin xyz="0.167 -0.05 -0.065" />
    <parent link="toeLeft" />
    <child link="leftFoot2" />
  </joint>
  <link
    name="leftFoot3">
    <inertial>
      <origin xyz="0 0 0" />
      <mass value="0.001" />
      <inertia 
        ixx="0.0001" 
        ixy="0" 
        ixz="0" 
        iyy="0.0001" 
        iyz="0" 
        izz="0.0001" />
    </inertial>
    <collision>
      <origin xyz="0 0 0" />
      <geometry>
        <sphere radius="0.001" />
      </geometry>
    </collision>
  </link>
  <joint
    name="leftFoot3"
    type="fixed">
    <origin xyz="-0.073 -0.05 -0.065" />
    <parent link="toeLeft" />
    <child link="leftFoot3" />
  </joint>
  <link
    name="leftFoot4">
    <inertial>
      <origin xyz="0 0 0" />
      <mass value="0.001" />
      <inertia 
        ixx="0.0001" 
        ixy="0" 
        ixz="0" 
        iyy="0.0001" 
        iyz="0" 
        izz="0.0001" />
    </inertial>
    <collision>
      <origin xyz="0 0 0" />
      <geometry>
        <sphere radius="0.001" />
      </geometry>
    </collision>
  </link>
  <joint
    name="leftFoot4"
    type="fixed">
    <origin xyz="-0.073 0.05 -0.065" />
    <parent link="toeLeft" />
    <child link="leftFoot4" />
  </joint>
  <link
    name="hipPitchRight">
    <inertial>
      <origin
        xyz="-0.05818164 -0.05886958 -0.00032981"
        rpy="0 0 0" />
      <mass
        value="2.15124254" />
      <inertia
        ixx="0.00385735"
        ixy="0.00094210"
        ixz="0.00002770"
        iyy="0.00440670"
        iyz="-0.00002677"
        izz="0.00508280" />
    </inertial>
    <visual>
      <origin
        xyz="0 0 0"
        rpy="0 0 0" />
      <geometry>
        <mesh
          filename="../meshes/hipPitchRight.STL" />
      </geometry>
      <material
        name="">
        <color
          rgba="1 1 1 1" />
      </material>
    </visual>
  </link>
  <joint
    name="hipPitch_Right"
    type="revolute">
    <origin
      xyz="0 -0.096192 -0.033241"
      rpy="0.61087 0 0" />
    <parent
      link="pelvis" />
    <child
      link="hipPitchRight" />
    <axis
      xyz="0 1 0" />
    <limit effort="230.0" lower="-2.09" upper="2.09" velocity="15.0"/>
  </joint>
  <link
    name="hipRollRight">
    <inertial>
      <origin
        xyz="0.03988167 0.00011594 -0.01102087"
        rpy="0 0 0" />
      <mass
        value="1.29422777" />
      <inertia
        ixx="0.00134170"
        ixy="0.00000379"
        ixz="-0.00006269"
        iyy="0.00136997"
        iyz="0.00001693"
        izz="0.00144502" />
    </inertial>
    <visual>
      <origin
        xyz="0 0 0"
        rpy="0 0 0" />
      <geometry>
        <mesh
          filename="../meshes/hipRollRight.STL" />
      </geometry>
      <material
        name="">
        <color
          rgba="1 1 1 1" />
      </material>
    </visual>
  </link>
  <joint
    name="hipRoll_Right"
    type="revolute">
    <origin
      xyz="-0.0255 -0.069 0"
      rpy="-0.61087 0 0" />
    <parent
      link="hipPitchRight" />
    <child
      link="hipRollRight" />
    <axis
      xyz="1 0 0" />
    <limit effort="160.0" lower="-1.57" upper="0.78" velocity="8.0"/>
  </joint>
  <link
    name="thighRight">
    <inertial>
      <origin
        xyz="0.00332701 0.01110269 -0.13528959"
        rpy="0 0 0" />
      <mass
        value="6.64754534" />
      <inertia
        ixx="0.05714386"
        ixy="0.00030277"
        ixz="-0.00153883"
        iyy="0.06243248"
        iyz="-0.00531134"
        izz="0.01517531" />
    </inertial>
    <visual>
      <origin
        xyz="0 0 0"
        rpy="0 0 0" />
      <geometry>
        <mesh
          filename="../meshes/thighRight.STL" />
      </geometry>
      <material
        name="">
        <color
          rgba="1 1 1 1" />
      </material>
    </visual>
  </link>
  <joint
    name="hipYaw_Right"
    type="revolute">
    <origin
      xyz="0.044 0 -0.0525"
      rpy="0 0 0" />
    <parent
      link="hipRollRight" />
    <child
      link="thighRight" />
    <axis
      xyz="0 0 1" />
    <limit effort="105" lower="-0.78" upper="0.78" velocity="8.0"/>
  </joint>
  <link
    name="shinRight">
    <inertial>
      <origin
        xyz="-0.00079979 -0.00097288 -0.14635087"
        rpy="0 0 0" />
      <mass
        value="2.20809154" />
      <inertia
        ixx="0.01979830"
        ixy="0.00001096"
        ixz="0.00021758"
        iyy="0.01987660"
        iyz="-0.00009064"
        izz="0.00137192" />
    </inertial>
    <visual>
      <origin
        xyz="0 0 0"
        rpy="0 0 0" />
      <geometry>
        <mesh
          filename="../meshes/shinRight.STL" />
      </geometry>
      <material
        name="">
        <color
          rgba="1 1 1 1" />
      </material>
    </visual>
    <collision>
      <origin
        xyz="0.0 0.0 -0.2"
        rpy="0 0 0" />
      <geometry>
        <box size="0.08 0.06 0.3"/>
      </geometry>
    </collision>
  </link>
  <joint
    name="kneePitch_Right"
    type="revolute">
    <origin
      xyz="0 0.0355 -0.369"
      rpy="0 0 0" />
    <parent
      link="thighRight" />
    <child
      link="shinRight" />
    <axis
      xyz="0 1 0" />
    <limit effort="230.0" lower="-0.09" upper="2.4" velocity="15.0"/>
  </joint>
  <link
    name="anklePitchRight">
    <inertial>
      <origin
        xyz="0.00000000 0.00000000 0.00000000"
        rpy="0 0 0" />
      <mass
        value="0.03100000" />
      <inertia
        ixx="0.00000323"
        ixy="0.00000000"
        ixz="0.00000000"
        iyy="0.00000323"
        iyz="0.00000000"
        izz="0.00000210" />
    </inertial>
    <visual>
      <origin
        xyz="0 0 0"
        rpy="0 0 0" />
      <geometry>
        <mesh
          filename="../meshes/anklePitchRight.STL" />
      </geometry>
      <material
        name="">
        <color
          rgba="0.752941176470588 0.752941176470588 0.752941176470588 1" />
      </material>
    </visual>
  </link>
  <joint
    name="anklePitch_Right"
    type="revolute">
    <origin
      xyz="0 0 -0.37"
      rpy="0 0 0" />
    <parent
      link="shinRight" />
    <child
      link="anklePitchRight" />
    <axis
      xyz="0 1 0" />
    <limit effort="40.0" lower="-1.0" upper="0.35" velocity="20.0"/>
  </joint>
  <link
    name="toeRight">
    <inertial>
      <origin
        xyz="0.03700297 0.00002151 -0.04197563"
        rpy="0 0 0" />
      <mass
        value="0.47580000" />
      <inertia
        ixx="0.00028522"
        ixy="-0.00001320"
        ixz="-0.00012034"
        iyy="0.00152191"
        iyz="-0.00000143"
        izz="0.00158164" />
    </inertial>
    <visual>
      <origin
        xyz="0 0 0"
        rpy="0 0 0" />
      <geometry>
        <mesh
          filename="../meshes/toeRight.STL" />
      </geometry>
      <material
        name="">
        <color
          rgba="0.752941176470588 0.752941176470588 0.752941176470588 1" />
      </material>
    </visual>
    <collision name="toe_right">
      <origin rpy="0 0 0" xyz="0.047 0.0 -0.05"/>
      <geometry>
        <box size="0.24 0.1 0.03"/>
      </geometry>
    </collision>
  </link>
  <joint
    name="ankleRoll_Right"
    type="revolute">
    <origin
      xyz="0 0 0"
      rpy="0 0 0" />
    <parent
      link="anklePitchRight" />
    <child
      link="toeRight" />
    <axis
      xyz="1 0 0" />
    <limit effort="12.0" lower="-0.3491" upper="0.3491" velocity="20.0"/>
  </joint>
  <link
    name="rightFoot1">
    <inertial>
      <origin xyz="0 0 0" />
      <mass value="0.001" />
      <inertia 
        ixx="0.0001" 
        ixy="0" 
        ixz="0" 
        iyy="0.0001" 
        iyz="0" 
        izz="0.0001" />
    </inertial>
    <collision>
      <origin xyz="0 0 0" />
      <geometry>
        <sphere radius="0.001" />
      </geometry>
    </collision>
  </link>
  <joint
    name="rightFoot1"
    type="fixed">
    <origin xyz="0.167 0.05 -0.065" />
    <parent link="toeRight" />
    <child link="rightFoot1" />
  </joint>
  <link
    name="rightFoot2">
    <inertial>
      <origin xyz="0 0 0" />
      <mass value="0.001" />
      <inertia 
        ixx="0.0001" 
        ixy="0" 
        ixz="0" 
        iyy="0.0001" 
        iyz="0" 
        izz="0.0001" />
    </inertial>
    <collision>
      <origin xyz="0 0 0" />
      <geometry>
        <sphere radius="0.001" />
      </geometry>
    </collision>
  </link>
  <joint
    name="rightFoot2"
    type="fixed">
    <origin xyz="0.167 -0.05 -0.065" />
    <parent link="toeRight" />
    <child link="rightFoot2" />
  </joint>
    <link
    name="rightFoot3">
    <inertial>
      <origin xyz="0 0 0" />
      <mass value="0.001" />
      <inertia 
        ixx="0.0001" 
        ixy="0" 
        ixz="0" 
        iyy="0.0001" 
        iyz="0" 
        izz="0.0001" />
    </inertial>
    <collision>
      <origin xyz="0 0 0" />
      <geometry>
        <sphere radius="0.001" />
      </geometry>
    </collision>
  </link>
  <joint
    name="rightFoot3"
    type="fixed">
    <origin xyz="-0.073 -0.05 -0.065" />
    <parent link="toeRight" />
    <child link="rightFoot3" />
  </joint>
    <link
    name="rightFoot4">
    <inertial>
      <origin xyz="0 0 0" />
      <mass value="0.001" />
      <inertia 
        ixx="0.0001" 
        ixy="0" 
        ixz="0" 
        iyy="0.0001" 
        iyz="0" 
        izz="0.0001" />
    </inertial>
    <collision>
      <origin xyz="0 0 0" />
      <geometry>
        <sphere radius="0.001" />
      </geometry>
    </collision>
  </link>
  <joint
    name="rightFoot4"
    type="fixed">
    <origin xyz="-0.073 0.05 -0.065" />
    <parent link="toeRight" />
    <child link="rightFoot4" />
  </joint>
  <link
    name="waistRoll">
    <inertial>
      <origin
        xyz="0.00212014 0.00212051 0.03999987"
        rpy="0 0 0" />
      <mass
        value="2.18430742" />
      <inertia
        ixx="0.00490282"
        ixy="-0.00000839"
        ixz="-0.00014940"
        iyy="0.00490290"
        iyz="0.00014939"
        izz="0.00201818" />
    </inertial>
    <visual>
      <origin
        xyz="0 0 0"
        rpy="0 0 0" />
      <geometry>
        <mesh
          filename="../meshes/waistRoll.STL" />
      </geometry>
      <material
        name="">
        <color
          rgba="1 1 1 1" />
      </material>
    </visual>
  </link>
  <joint
    name="waistRoll"
    type="revolute">
    <origin
      xyz="0 0 0.044"
      rpy="0 0 0" />
    <parent
      link="pelvis" />
    <child
      link="waistRoll" />
    <axis
      xyz="1 0 0" />
    <limit effort="110" lower="-0.52" upper="0.52" velocity="8.0"/>
  </joint>
  <link
    name="waistPitch">
    <inertial>
      <origin
        xyz="-0.00066627 0.00070478 0.02506554"
        rpy="0 0 0" />
      <mass
        value="0.49870000" />
      <inertia
        ixx="0.00136060"
        ixy="0.00000019"
        ixz="-0.00000061"
        iyy="0.00061064"
        iyz="-0.00002570"
        izz="0.00144067" />
    </inertial>
    <visual>
      <origin
        xyz="0 0 0"
        rpy="0 0 0" />
      <geometry>
        <mesh
          filename="../meshes/waistPitch.STL" />
      </geometry>
      <material
        name="">
        <color
          rgba="1 1 1 1" />
      </material>
    </visual>
  </link>
  <joint
    name="waistPitch"
    type="revolute">
    <origin
      xyz="0 0 0.08"
      rpy="0 0 0" />
    <parent
      link="waistRoll" />
    <child
      link="waistPitch" />
    <axis
      xyz="0 1 0" />
    <limit effort="110" lower="-0.78" upper="0.78" velocity="8.0"/>
  </joint>
  <link
    name="torso">
    <inertial>
      <origin
        xyz="0.00080019 -0.00003149 0.18300318"
        rpy="0 0 0" />
      <mass
        value="13.28595962" />
      <inertia
        ixx="0.19892857"
        ixy="0.00002898"
        ixz="0.00372210"
        iyy="0.16115382"
        iyz="-0.00010404"
        izz="0.07256954" />
    </inertial>
    <visual>
      <origin
        xyz="0 0 0"
        rpy="0 0 0" />
      <geometry>
        <mesh
          filename="../meshes/torso.STL" />
      </geometry>
      <material
        name="">
        <color
          rgba="0.752941176470588 0.752941176470588 0.752941176470588 1" />
      </material>
    </visual>
    <collision>
      <origin
        xyz="0 0 0.15"
        rpy="0 0 0" />
      <geometry>
        <sphere radius="0.13"/>
      </geometry>
    </collision>
  </link>
  <joint
    name="waistYaw"
    type="revolute">
    <origin
      xyz="0 0.0005 0.053"
      rpy="0 0 0" />
    <parent
      link="waistPitch" />
    <child
      link="torso" />
    <axis
      xyz="0 0 1" />
    <limit effort="110" lower="-0.78" upper="0.78" velocity="8.0"/>
  </joint>
  <link
    name="shoulderPitchLeft">
    <inertial>
      <origin
        xyz="-0.00150404 0.02688841 0.00010848"
        rpy="0 0 0" />
      <mass
        value="0.20310000" />
      <inertia
        ixx="0.00017020"
        ixy="-0.00000461"
        ixz="-0.00000064"
        iyy="0.00028895"
        iyz="0.00000042"
        izz="0.00034385" />
    </inertial>
    <visual>
      <origin
        xyz="0 0 0"
        rpy="0 0 0" />
      <geometry>
        <mesh
          filename="../meshes/shoulderPitchLeft.STL" />
      </geometry>
      <material
        name="">
        <color
          rgba="1 1 1 1" />
      </material>
    </visual>
  </link>
  <joint
    name="shoulderPitch_Left"
    type="revolute">
    <origin
      xyz="0 0.16011 0.25742"
      rpy="0.34907 0 0" />
    <parent
      link="torso" />
    <child
      link="shoulderPitchLeft" />
    <axis
      xyz="0 1 0" />
    <limit effort="65.0" lower="-2.7" upper="1.0" velocity="8.0"/>
  </joint>
  <link
    name="shoulderRollLeft">
    <inertial>
      <origin
        xyz="-0.02860447 0.01104245 -0.01405309"
        rpy="0 0 0" />
      <mass
        value="0.72480000" />
      <inertia
        ixx="0.00090812"
        ixy="-0.00002621"
        ixz="0.00003997"
        iyy="0.00071197"
        iyz="-0.00025129"
        izz="0.00060954" />
    </inertial>
    <visual>
      <origin
        xyz="0 0 0"
        rpy="0 0 0" />
      <geometry>
        <mesh
          filename="../meshes/shoulderRollLeft.STL" />
      </geometry>
      <material
        name="">
        <color
          rgba="1 1 1 1" />
      </material>
    </visual>
    <collision>
      <origin
        xyz="-0.03 0 0"
        rpy="0 1.5708 0" />
      <geometry>
        <cylinder length="0.1" radius="0.035"/>
      </geometry>
    </collision>
  </link>
  <joint
    name="shoulderRoll_Left"
    type="revolute">
    <origin
      xyz="0.0335 0.0435 0"
      rpy="-0.34907 0 0" />
    <parent
      link="shoulderPitchLeft" />
    <child
      link="shoulderRollLeft" />
    <axis
      xyz="1 0 0" />
    <limit effort="65.0" lower="-0.3" upper="3.14" velocity="8.0"/> 
  </joint>
  <link
    name="shoulderYawLeft">
    <inertial>
      <origin
        xyz="-0.00069813 0.00102049 -0.06842313"
        rpy="0 0 0" />
      <mass
        value="0.69630000" />
      <inertia
        ixx="0.00317887"
        ixy="0.00000059"
        ixz="0.00005528"
        iyy="0.00310433"
        iyz="-0.00009472"
        izz="0.00039452" />
    </inertial>
    <visual>
      <origin
        xyz="0 0 0"
        rpy="0 0 0" />
      <geometry>
        <mesh
          filename="../meshes/shoulderYawLeft.STL" />
      </geometry>
      <material
        name="">
        <color
          rgba="1 1 1 1" />
      </material>
    </visual>
    <collision>
      <origin
        xyz="0 0. -0.08"
        rpy="0 0 0" />
      <geometry>
        <cylinder length="0.15" radius="0.038"/>
      </geometry>
    </collision>
  </link>
  <joint
    name="shoulderYaw_Left"
    type="revolute">
    <origin
      xyz="-0.0335 0.034 -0.0585"
      rpy="0 0 0" />
    <parent
      link="shoulderRollLeft" />
    <child
      link="shoulderYawLeft" />
    <axis
      xyz="0 0 1" />
    <limit effort="65.0" lower="-1.6" upper="1.6" velocity="8.0"/>
  </joint>
  <link
    name="elbowLeft">
    <inertial>
      <origin
        xyz="-0.02164423 0.02776208 -0.04469642"
        rpy="0 0 0" />
      <mass
        value="0.85400000" />
      <inertia
        ixx="0.00072987"
        ixy="-0.00001380"
        ixz="0.00015644"
        iyy="0.00080410"
        iyz="-0.00002763"
        izz="0.00047565" />
    </inertial>
    <visual>
      <origin
        xyz="0 0 0"
        rpy="0 0 0" />
      <geometry>
        <mesh
          filename="../meshes/elbowLeft.STL" />
      </geometry>
      <material
        name="">
        <color
          rgba="1 1 1 1" />
      </material>
    </visual>
  </link>
  <joint
    name="elbow_Left"
    type="revolute">
    <origin
      xyz="0 -0.0285 -0.20415"
      rpy="0 0 0" />
    <parent
      link="shoulderYawLeft" />
    <child
      link="elbowLeft" />
    <axis
      xyz="0 1 0" />
    <limit effort="30.0" lower="-2.0" upper="0.0" velocity="8.0"/>
  </joint>
  <link
    name="wristYawLeft">
    <inertial>
      <origin
        xyz="-0.000619 0.000018 -0.110099"
        rpy="0 0 0" />
      <mass
        value="1.128365" />
      <inertia
        ixx="0.004351"
        ixy="-0.000002"
        ixz="0.000018"
        iyy="0.004285"
        iyz="-0.000061"
        izz="0.000583" />
    </inertial>
    <visual>
      <origin
        xyz="0 0 0"
        rpy="0 0 0" />
      <geometry>
        <mesh
          filename="../meshes/wristYawLeft.STL" />
      </geometry>
      <material
        name="">
        <color
          rgba="1 1 1 1" />
      </material>
    </visual>
  </link>
  <joint
    name="wristYaw_Left"
    type="fixed">
    <origin
      xyz="-0.025 0.0285 -0.0729"
      rpy="0 0 0" />
    <parent
      link="elbowLeft" />
    <child
      link="wristYawLeft" />
    <axis
      xyz="0 0 1" />
  </joint>
  <link
    name="wristPitchLeft">
    <inertial>
      <origin
        xyz="-0.000148 0.000000 -0.000056"
        rpy="0 0 0" />
      <mass
        value="0.070400" />
      <inertia
        ixx="0.000024"
        ixy="0.000000"
        ixz="0.000000"
        iyy="0.000016"
        iyz="0.000000"
        izz="0.000027" />
    </inertial>
    <visual>
      <origin
        xyz="0 0 0"
        rpy="0 0 0" />
      <geometry>
        <mesh
          filename="../meshes/wristPitchLeft.STL" />
      </geometry>
      <material
        name="">
        <color
          rgba="1 1 1 1" />
      </material>
    </visual>
  </link>
  <joint
    name="wristPitch_Left"
    type="fixed">
    <origin
      xyz="0 0 -0.2232"
      rpy="0 0 0" />
    <parent
      link="wristYawLeft" />
    <child
      link="wristPitchLeft" />
    <axis
      xyz="0 1 0" />
  </joint>
  <link
    name="wristRollLeft">
    <inertial>
      <origin
        xyz="-0.000223 0.005751 -0.061251"
        rpy="0 0 0" />
      <mass
        value="0.262935" />
      <inertia
        ixx="0.000289"
        ixy="0.000002"
        ixz="-0.000001"
        iyy="0.000256"
        iyz="-0.000072"
        izz="0.000182" />
    </inertial>
    <visual>
      <origin
        xyz="0 0 0"
        rpy="0 0 0" />
      <geometry>
        <mesh
          filename="../meshes/wristRollLeft.STL" />
      </geometry>
      <material
        name="">
        <color
          rgba="1 1 1 1" />
      </material>
    </visual>
  </link>
  <joint
    name="wristRoll_Left"
    type="fixed">
    <origin
      xyz="0 0 0"
      rpy="0 0 0" />
    <parent
      link="wristPitchLeft" />
    <child
      link="wristRollLeft" />
    <axis
      xyz="1 0 0" />
  </joint>
  <link
    name="gripperLeft">
    <inertial>
      <origin
        xyz="-0.017101 -0.010945 -0.034180"
        rpy="0 0 0" />
      <mass
        value="0.042000" />
      <inertia
        ixx="0.000029"
        ixy="0.000000"
        ixz="0.000001"
        iyy="0.000033"
        iyz="0.000004"
        izz="0.000009" />
    </inertial>
    <visual>
      <origin
        xyz="0 0 0"
        rpy="0 0 0" />
      <geometry>
        <mesh
          filename="../meshes/gripperLeft.STL" />
      </geometry>
      <material
        name="">
        <color
          rgba="1 1 1 1" />
      </material>
    </visual>
  </link>
  <joint
    name="gripper_Left"
    type="fixed">
    <origin
      xyz="0.017508 -0.019 -0.052997"
      rpy="0 0 0" />
    <parent
      link="wristRollLeft" />
    <child
      link="gripperLeft" />
    <axis
      xyz="1 0 0" />
  </joint>
  <link
    name="shoulderPitchRight">
    <inertial>
      <origin
        xyz="-0.00150404 -0.02687227 0.00010766"
        rpy="0 0 0" />
      <mass
        value="0.20310000" />
      <inertia
        ixx="0.00017009"
        ixy="0.00000447"
        ixz="-0.00000064"
        iyy="0.00028895"
        iyz="-0.00000043"
        izz="0.00034374" />
    </inertial>
    <visual>
      <origin
        xyz="0 0 0"
        rpy="0 0 0" />
      <geometry>
        <mesh
          filename="../meshes/shoulderPitchRight.STL" />
      </geometry>
      <material
        name="">
        <color
          rgba="1 1 1 1" />
      </material>
    </visual>
  </link>
  <joint
    name="shoulderPitch_Right"
    type="revolute">
    <origin
      xyz="0 -0.16011 0.25742"
      rpy="-0.34907 0 0" />
    <parent
      link="torso" />
    <child
      link="shoulderPitchRight" />
    <axis
      xyz="0 1 0" />
    <limit effort="65.0" lower="-2.7" upper="1.1" velocity="8.0"/>
  </joint>
  <link
    name="shoulderRollRight">
    <inertial>
      <origin
        xyz="-0.02860454 -0.01104592 -0.01404986"
        rpy="0 0 0" />
      <mass
        value="0.72480000" />
      <inertia
        ixx="0.00090814"
        ixy="0.00002628"
        ixz="0.00003990"
        iyy="0.00071184"
        iyz="0.00025129"
        izz="0.00060969" />
    </inertial>
    <visual>
      <origin
        xyz="0 0 0"
        rpy="0 0 0" />
      <geometry>
        <mesh
          filename="../meshes/shoulderRollRight.STL" />
      </geometry>
      <material
        name="">
        <color
          rgba="1 1 1 1" />
      </material>
    </visual>
    <collision>
      <origin
        xyz="-0.03 0 0"
        rpy="0 1.5708 0" />
      <geometry>
        <cylinder length="0.1" radius="0.035"/>
      </geometry>
    </collision>
  </link>
  <joint
    name="shoulderRoll_Right"
    type="revolute">
    <origin
      xyz="0.0335 -0.0435 0"
      rpy="0.34907 0 0" />
    <parent
      link="shoulderPitchRight" />
    <child
      link="shoulderRollRight" />
    <axis
      xyz="1 0 0" />
    <limit effort="65.0" lower="-3.14" upper="0.3" velocity="8.0"/>
  </joint>
  <link
    name="shoulderYawRight">
    <inertial>
      <origin
        xyz="-0.00089274 -0.00096643 -0.06980518"
        rpy="0 0 0" />
      <mass
        value="0.69630000" />
      <inertia
        ixx="0.00304636"
        ixy="-0.00000070"
        ixz="0.00005211"
        iyy="0.00297764"
        iyz="0.00008904"
        izz="0.00041751" />
    </inertial>
    <visual>
      <origin
        xyz="0 0 0"
        rpy="0 0 0" />
      <geometry>
        <mesh
          filename="../meshes/shoulderYawRight.STL" />
      </geometry>
      <material
        name="">
        <color
          rgba="1 1 1 1" />
      </material>
    </visual>
    <collision>
      <origin
        xyz="0 0. -0.08"
        rpy="0 0 0" />
      <geometry>
        <cylinder length="0.15" radius="0.038"/>
      </geometry>
    </collision>
  </link>
  <joint
    name="shoulderYaw_Right"
    type="revolute">
    <origin
      xyz="-0.0335 -0.034 -0.0585"
      rpy="0 0 0" />
    <parent
      link="shoulderRollRight" />
    <child
      link="shoulderYawRight" />
    <axis
      xyz="0 0 1" />
    <limit effort="65.0" lower="-1.6" upper="1.6" velocity="8.0"/>
  </joint>
  <link
    name="elbowRight">
    <inertial>
      <origin
        xyz="-0.01212328 -0.02629569 -0.02658404"
        rpy="0 0 0" />
      <mass
        value="0.85400000" />
      <inertia
        ixx="0.00099546"
        ixy="0.00002241"
        ixz="0.00027937"
        iyy="0.00111379"
        iyz="0.00004820"
        izz="0.00053993" />
    </inertial>
    <visual>
      <origin
        xyz="0 0 0"
        rpy="0 0 0" />
      <geometry>
        <mesh
          filename="../meshes/elbowRight.STL" />
      </geometry>
      <material
        name="">
        <color
          rgba="1 1 1 1" />
      </material>
    </visual>
  </link>
  <joint
    name="elbow_Right"
    type="revolute">
    <origin
      xyz="0 0.0285 -0.20415"
      rpy="0 0 0" />
    <parent
      link="shoulderYawRight" />
    <child
      link="elbowRight" />
    <axis
      xyz="0 1 0" />
    <limit effort="30.0" lower="-2.0" upper="0.0" velocity="8.0"/>
  </joint>
  <link
    name="wristYawRight">
    <inertial>
      <origin
        xyz="-0.000272 -0.000124 -0.105239"
        rpy="0 0 0" />
      <mass
        value="1.128360" />
      <inertia
        ixx="0.003968"
        ixy="0.000004"
        ixz="0.000010"
        iyy="0.003912"
        iyz="0.000061"
        izz="0.000565" />
    </inertial>
    <visual>
      <origin
        xyz="0 0 0"
        rpy="0 0 0" />
      <geometry>
        <mesh
          filename="../meshes/wristYawRight.STL" />
      </geometry>
      <material
        name="">
        <color
          rgba="1 1 1 1" />
      </material>
    </visual>
  </link>
  <joint
    name="wristYaw_Right"
    type="fixed">
    <origin
      xyz="-0.025 -0.0285 -0.0729"
      rpy="0 0 0" />
    <parent
      link="elbowRight" />
    <child
      link="wristYawRight" />
    <axis
      xyz="0 0 1" />
  </joint>
  <link
    name="wristPitchRight">
    <inertial>
      <origin
        xyz="0.000169 -0.001906 -0.000061"
        rpy="0 0 0" />
      <mass
        value="0.070400" />
      <inertia
        ixx="0.000025"
        ixy="0.000000"
        ixz="0.000000"
        iyy="0.000016"
        iyz="0.000000"
        izz="0.000027" />
    </inertial>
    <visual>
      <origin
        xyz="0 0 0"
        rpy="0 0 0" />
      <geometry>
        <mesh
          filename="../meshes/wristPitchRight.STL" />
      </geometry>
      <material
        name="">
        <color
          rgba="1 1 1 1" />
      </material>
    </visual>
  </link>
  <joint
    name="wristPitch_Right"
    type="fixed">
    <origin
      xyz="0 0 -0.2232"
      rpy="0 0 0" />
    <parent
      link="wristYawRight" />
    <child
      link="wristPitchRight" />
    <axis
      xyz="0 1 0" />
  </joint>
  <link
    name="wristRollRight">
    <inertial>
      <origin
        xyz="0.000232 -0.005751 -0.061251"
        rpy="0 0 0" />
      <mass
        value="0.262935" />
      <inertia
        ixx="0.000289"
        ixy="0.000002"
        ixz="0.000001"
        iyy="0.000256"
        iyz="0.000072"
        izz="0.000182" />
    </inertial>
    <visual>
      <origin
        xyz="0 0 0"
        rpy="0 0 0" />
      <geometry>
        <mesh
          filename="../meshes/wristRollRight.STL" />
      </geometry>
      <material
        name="">
        <color
          rgba="1 1 1 1" />
      </material>
    </visual>
  </link>
  <joint
    name="wristRoll_Right"
    type="fixed">
    <origin
      xyz="0 0 0"
      rpy="0 0 0" />
    <parent
      link="wristPitchRight" />
    <child
      link="wristRollRight" />
    <axis
      xyz="1 0 0" />
  </joint>
  <link
    name="gripperRight">
    <inertial>
      <origin
        xyz="0.017106 0.010945 -0.034178"
        rpy="0 0 0" />
      <mass
        value="0.042000" />
      <inertia
        ixx="0.000029"
        ixy="0.000000"
        ixz="-0.000001"
        iyy="0.000033"
        iyz="-0.000004"
        izz="0.000009" />
    </inertial>
    <visual>
      <origin
        xyz="0 0 0"
        rpy="0 0 0" />
      <geometry>
        <mesh
          filename="../meshes/gripperRight.STL" />
      </geometry>
      <material
        name="">
        <color
          rgba="1 1 1 1" />
      </material>
    </visual>
  </link>
  <joint
    name="gripper_Right"
    type="fixed">
    <origin
      xyz="-0.0175 0.019 -0.053"
      rpy="0 0 0" />
    <parent
      link="wristRollRight" />
    <child
      link="gripperRight" />
    <axis
      xyz="1 0 0" />
  </joint>
</robot>