<?xml version="1.0" encoding="utf-8"?>
<!-- This URDF was automatically created by SolidWorks to URDF Exporter! Originally created by Stephen Brawner (brawner@gmail.com) 
     Commit Version: 1.6.0-4-g7f85cfe  Build Version: 1.6.7995.38578
     For more information, please see http://wiki.ros.org/sw_urdf_exporter -->
<robot
  name="adam">
  <link
    name="pelvis">
    <inertial>
      <origin
        xyz="0.000083 0.0 -0.001091"
        rpy="0 0 0" />
      <mass
        value="9.240301" />
      <inertia
        ixx="0.054213"
        ixy="0.000005"
        ixz="0.000024"
        iyy="0.027698"
        iyz="0.000000"
        izz="0.058691" />
    </inertial>
    <visual>
      <origin
        xyz="0 0 0"
        rpy="0 0 0" />
      <geometry>
        <mesh
          filename="../meshes/base.obj" />
      </geometry>
      <material
        name="">
        <color
          rgba="0.752941176470588 0.752941176470588 0.752941176470588 1" />
      </material>
    </visual>
    <collision>
      <origin
        xyz="0.0 0.0 0.0"
        rpy="0.0 0 0" />
      <geometry>
        <mesh filename="../meshes/base.obj"/>
      </geometry>
    </collision>
  </link>
  <link
    name="hipPitchLeft">
    <inertial>
      <origin
        xyz="-0.060710 0.058995 -0.000274"
        rpy="0 0 0" />
      <mass
        value="2.122960" />
      <inertia
        ixx="0.003430"
        ixy="-0.000980"
        ixz="-0.000017"
        iyy="0.004095"
        iyz="0.000026"
        izz="0.004706" />
    </inertial>
    <visual>
      <origin
        xyz="0 0 0"
        rpy="0 0 0" />
      <geometry>
        <mesh
          filename="../meshes/zuotui-kuance.obj" />
      </geometry>
      <material
        name="">
        <color
          rgba="0.752941176470588 0.752941176470588 0.752941176470588 1" />
      </material>
    </visual>
    <collision>
      <origin
        xyz="0.0 0.0 0.0"
        rpy="0.0 0 0" />
      <geometry>
        <mesh filename="../meshes/zuotui-kuance.obj"/>
      </geometry>
    </collision>
  </link>
  <joint
    name="hipPitch_Left"
    type="revolute">
    <origin
      xyz="0 0.096102 -0.027011"
      rpy="-0.61087 0 0" />
    <parent
      link="pelvis" />
    <child
      link="hipPitchLeft" />
    <axis
      xyz="0 1 0" />
    <limit effort="230.0" lower="-2.09" upper="2.09" velocity="15.0"/>
  </joint>
  <link
    name="hipRollLeft">
    <inertial>
      <origin
        xyz="0.039593 -0.000453 -0.010045"
        rpy="0 0 0" />
      <mass
        value="1.302398" />
      <inertia
        ixx="0.001122"
        ixy="-0.000001"
        ixz="-0.000076"
        iyy="0.001194"
        iyz="-0.000015"
        izz="0.001338" />
    </inertial>
    <visual>
      <origin
        xyz="0 0 0"
        rpy="0 0 0" />
      <geometry>
        <mesh
          filename="../meshes/zuotui-kuanzhuan.obj" />
      </geometry>
      <material
        name="">
        <color
          rgba="0.752941176470588 0.752941176470588 0.752941176470588 1" />
      </material>
    </visual>
    <collision>
      <origin
        xyz="0.0 0.0 0.0"
        rpy="0.0 0 0" />
      <geometry>
        <mesh filename="../meshes/zuotui-kuanzhuan.obj"/>
      </geometry>
    </collision>
  </link>
  <joint
    name="hipRoll_Left"
    type="revolute">
    <origin
      xyz="-0.0255 0.069 0"
      rpy="0.61087 0 0" />
    <parent
      link="hipPitchLeft" />
    <child
      link="hipRollLeft" />
    <axis
      xyz="1 0 0" />
    <limit effort="160.0" lower="-0.78" upper="1.57" velocity="8.0"/>
  </joint>
  <link
    name="thigh_Left">
    <inertial>
      <origin
        xyz="0.003802 -0.008180 -0.130931"
        rpy="0 0 0" />
      <mass
        value="6.098905" />
      <inertia
        ixx="0.051840"
        ixy="-0.000234"
        ixz="-0.000840"
        iyy="0.057183"
        iyz="0.005427"
        izz="0.012216" />
    </inertial>
    <visual>
      <origin
        xyz="0 0 0"
        rpy="0 0 0" />
      <geometry>
        <mesh
          filename="../meshes/zuotui-datui.obj" />
      </geometry>
      <material
        name="">
        <color
          rgba="0.752941176470588 0.752941176470588 0.752941176470588 1" />
      </material>
    </visual>
    <collision>
      <origin
        xyz="0.0 0.0 0.0"
        rpy="0.0 0 0" />
      <geometry>
        <mesh filename="../meshes/zuotui-datui.obj"/>
      </geometry>
    </collision>
  </link>
  <joint
    name="hipYaw_Left"
    type="revolute">
    <origin
      xyz="0.044 0 -0.0525"
      rpy="0 0 0" />
    <parent
      link="hipRollLeft" />
    <child
      link="thigh_Left" />
    <axis
      xyz="0 0 1" />
    <limit effort="105" lower="-0.78" upper="0.78" velocity="8.0"/>
  </joint>
  <link
    name="shin_Left">
    <inertial>
      <origin
        xyz="0.000004 0.000631 -0.145751"
        rpy="0 0 0" />
      <mass
        value="2.240625" />
      <inertia
        ixx="0.023481"
        ixy="-0.000020"
        ixz="0.000210"
        iyy="0.023543"
        iyz="0.000576"
        izz="0.001345" />
    </inertial>
    <visual>
      <origin
        xyz="0 0 0"
        rpy="0 0 0" />
      <geometry>
        <mesh
          filename="../meshes/zuotui-xiaotui.obj" />
      </geometry>
      <material
        name="">
        <color
          rgba="0.752941176470588 0.752941176470588 0.752941176470588 1" />
      </material>
    </visual>
    <collision>
      <origin
        xyz="0.0 0.0 0.0"
        rpy="0.0 0 0" />
      <geometry>
        <mesh filename="../meshes/zuotui-xiaotui.obj"/>
      </geometry>
    </collision>
  </link>
  <joint
    name="kneePitch_Left"
    type="revolute">
    <origin
      xyz="0 -0.0355 -0.369"
      rpy="0 0 0" />
    <parent
      link="thigh_Left" />
    <child
      link="shin_Left" />
    <axis
      xyz="0 1 0" />
    <limit effort="230.0" lower="-0.09" upper="2.4" velocity="15.0"/>
  </joint>
  <link
    name="footLeftY">
    <inertial>
      <origin
        xyz="0 0 0"
        rpy="0 0 0" />
      <mass
        value="0.052131" />
      <inertia
        ixx="0.000005"
        ixy="0"
        ixz="0"
        iyy="0.000005"
        iyz="0"
        izz="0.000004" />
    </inertial>
    <visual>
      <origin
        xyz="0 0 0"
        rpy="0 0 0" />
      <geometry>
        <mesh
          filename="../meshes/zuotui-huaiqianbai.obj" />
      </geometry>
      <material
        name="">
        <color
          rgba="0.529411764705882 0.549019607843137 0.549019607843137 1" />
      </material>
    </visual>
    <collision>
      <origin
        xyz="0.0 0.0 0.0"
        rpy="0.0 0 0" />
      <geometry>
        <mesh filename="../meshes/zuotui-huaiqianbai.obj"/>
      </geometry>
    </collision>
  </link>
  <joint
    name="anklePitch_Left"
    type="revolute">
    <origin
      xyz="0 0 -0.37"
      rpy="0 0 0" />
    <parent
      link="shin_Left" />
    <child
      link="footLeftY" />
    <axis
      xyz="0 1 0" />
    <limit effort="40.0" lower="-1.0" upper="0.35" velocity="20.0"/>
  </joint>
  <link
    name="toe_left">
    <inertial>
      <origin
        xyz="0.037497 -0.000454 -0.034086"
        rpy="0 0 0" />
      <mass
        value="0.434898" />
      <inertia
        ixx="0.000207"
        ixy="0.000030"
        ixz="-0.000134"
        iyy="0.001240"
        iyz="0.000003"
        izz="0.001289" />
    </inertial>
    <visual>
      <origin
        xyz="0 0 0"
        rpy="0 0 0" />
      <geometry>
        <mesh
          filename="../meshes/zuotui-jiao.obj" />
      </geometry>
      <material
        name="">
        <color
          rgba="0.752941176470588 0.752941176470588 0.752941176470588 1" />
      </material>
    </visual>
    <collision>
      <origin
        xyz="0.0 0.0 0.0"
        rpy="0.0 0 0" />
      <geometry>
        <mesh filename="../meshes/zuotui-jiao.obj"/>
      </geometry>
    </collision>
  </link>
  <joint
    name="ankleRoll_Left"
    type="revolute">
    <origin
      xyz="0 0 0"
      rpy="0 0 0" />
    <parent
      link="footLeftY" />
    <child
      link="toe_left" />
    <axis
      xyz="1 0 0" />
    <limit effort="12.0" lower="-0.3491" upper="0.3491" velocity="20.0"/>
  </joint>
  <link
    name="hipPitchRight">
    <inertial>
      <origin
        xyz="-0.060710 -0.058995 -0.000274"
        rpy="0 0 0" />
      <mass
        value="2.122960" />
      <inertia
        ixx="0.003430"
        ixy="0.000980"
        ixz="-0.000017"
        iyy="0.004095"
        iyz="-0.000026"
        izz="0.004706" />
    </inertial>
    <visual>
      <origin
        xyz="0 0 0"
        rpy="0 0 0" />
      <geometry>
        <mesh
          filename="../meshes/youtui-kuance.obj" />
      </geometry>
      <material
        name="">
        <color
          rgba="0.752941176470588 0.752941176470588 0.752941176470588 1" />
      </material>
    </visual>
    <collision>
      <origin
        xyz="0.0 0.0 0.0"
        rpy="0.0 0 0" />
      <geometry>
        <mesh filename="../meshes/youtui-kuance.obj"/>
      </geometry>
    </collision>
  </link>
  <joint
    name="hipPitch_Right"
    type="revolute">
    <origin
      xyz="0 -0.096102 -0.027011"
      rpy="0.61087 0 0" />
    <parent
      link="pelvis" />
    <child
      link="hipPitchRight" />
    <axis
      xyz="0 1 0" />
    <limit effort="230.0" lower="-2.09" upper="2.09" velocity="15.0"/>
  </joint>
  <link
    name="hipRollRight">
    <inertial>
      <origin
        xyz="0.039593 0.000453 -0.010045"
        rpy="0 0 0" />
      <mass
        value="1.302398" />
      <inertia
        ixx="0.001122"
        ixy="0.000001"
        ixz="-0.000076"
        iyy="0.001194"
        iyz="0.000015"
        izz="0.001338" />
    </inertial>
    <visual>
      <origin
        xyz="0 0 0"
        rpy="0 0 0" />
      <geometry>
        <mesh
          filename="../meshes/youtui-kuanzhuan.obj" />
      </geometry>
      <material
        name="">
        <color
          rgba="0.752941176470588 0.752941176470588 0.752941176470588 1" />
      </material>
    </visual>
    <collision>
      <origin
        xyz="0.0 0.0 0.0"
        rpy="0.0 0 0" />
      <geometry>
        <mesh filename="../meshes/youtui-kuanzhuan.obj"/>
      </geometry>
    </collision>
  </link>
  <joint
    name="hipRoll_Right"
    type="revolute">
    <origin
      xyz="-0.0255 -0.069 0"
      rpy="-0.61087 0 0" />
    <parent
      link="hipPitchRight" />
    <child
      link="hipRollRight" />
    <axis
      xyz="1 0 0" />
    <limit effort="160.0" lower="-1.57" upper="0.78" velocity="8.0"/>
  </joint>
  <link
    name="thigh_Right">
    <inertial>
      <origin
        xyz="0.003802 0.008180 -0.130931"
        rpy="0 0 0" />
      <mass
        value="6.098905" />
      <inertia
        ixx="0.051840"
        ixy="0.000234"
        ixz="-0.000840"
        iyy="0.057183"
        iyz="-0.005427"
        izz="0.012216" />
    </inertial>
    <visual>
      <origin
        xyz="0 -0.003 0"
        rpy="0 0 0" />
      <geometry>
        <mesh
          filename="../meshes/youtui-datui.obj" />
      </geometry>
      <material
        name="">
        <color
          rgba="0.752941176470588 0.752941176470588 0.752941176470588 1" />
      </material>
    </visual>
    <collision>
      <origin
        xyz="0.0 0.0 0.0"
        rpy="0.0 0 0" />
      <geometry>
        <mesh filename="../meshes/youtui-datui.obj"/>
      </geometry>
    </collision>
  </link>
  <joint
    name="hipYaw_Right"
    type="revolute">
    <origin
      xyz="0.044 0.0 -0.0525"
      rpy="0 0 0" />
    <parent
      link="hipRollRight" />
    <child
      link="thigh_Right" />
    <axis
      xyz="0 0 1" />
    <limit effort="105" lower="-0.78" upper="0.78" velocity="8.0"/>
  </joint>
  <link
    name="shin_Right">
    <inertial>
      <origin
        xyz="0.000004 -0.000631 -0.145751"
        rpy="0 0 0" />
      <mass
        value="2.240625" />
      <inertia
        ixx="0.023481"
        ixy="0.000020"
        ixz="0.000210"
        iyy="0.023543"
        iyz="-0.000576"
        izz="0.001345" />
    </inertial>
    <visual>
      <origin
        xyz="0 0 0"
        rpy="0 0 0" />
      <geometry>
        <mesh
          filename="../meshes/youtui-xiaotui.obj" />
      </geometry>
      <material
        name="">
        <color
          rgba="0.752941176470588 0.752941176470588 0.752941176470588 1" />
      </material>
    </visual>
    <collision>
      <origin
        xyz="0.0 0.0 0.0"
        rpy="0.0 0 0" />
      <geometry>
        <mesh filename="../meshes/youtui-xiaotui.obj"/>
      </geometry>
    </collision>
  </link>
  <joint
    name="kneePitch_Right"
    type="revolute">
    <origin
      xyz="0 0.0355 -0.369"
      rpy="0 0 0" />
    <parent
      link="thigh_Right" />
    <child
      link="shin_Right" />
    <axis
      xyz="0 1 0" />
    <limit effort="230.0" lower="-0.09" upper="2.4" velocity="15.0"/>
  </joint>
  <link
    name="footRightY">
    <inertial>
      <origin
        xyz="0 0 0"
        rpy="0 0 0" />
      <mass
        value="0.052131" />
      <inertia
        ixx="0.000005"
        ixy="0"
        ixz="0"
        iyy="0.000005"
        iyz="0"
        izz="0.000004" />
    </inertial>
    <visual>
      <origin
        xyz="0 0 0"
        rpy="0 0 0" />
      <geometry>
        <mesh
          filename="../meshes/youtui-huaiqianbai.obj" />
      </geometry>
      <material
        name="">
        <color
          rgba="0.529411764705882 0.549019607843137 0.549019607843137 1" />
      </material>
    </visual>
    <collision>
      <origin
        xyz="0.0 0.0 0.0"
        rpy="0 0 0" />
      <geometry>
        <mesh
          filename="../meshes/youtui-huaiqianbai.obj" />
      </geometry>
    </collision>
  </link>
  <joint
    name="anklePitch_Right"
    type="revolute">
    <origin
      xyz="0 0 -0.37"
      rpy="0 0 0" />
    <parent
      link="shin_Right" />
    <child
      link="footRightY" />
    <axis
      xyz="0 1 0" />
    <limit effort="40.0" lower="-1.0" upper="0.35" velocity="20.0"/>
  </joint>
  <link
    name="toe_right">
    <inertial>
      <origin
        xyz="0.037497 0.000454 -0.034086"
        rpy="0 0 0" />
      <mass
        value="0.434898" />
      <inertia
        ixx="0.000207"
        ixy="-0.000030"
        ixz="-0.000134"
        iyy="0.001240"
        iyz="-0.000003"
        izz="0.001289" />
    </inertial>
    <visual>
      <origin
        xyz="0 0 0"
        rpy="0 0 0" />
      <geometry>
        <mesh
          filename="../meshes/youtui-jiao.obj" />
      </geometry>
      <material
        name="">
        <color
          rgba="0.752941176470588 0.752941176470588 0.752941176470588 1" />
      </material>
    </visual>
    <collision>
      <origin
        xyz="0.0 0.0 0.0"
        rpy="0 0 0" />
      <geometry>
        <mesh
          filename="../meshes/youtui-jiao.obj" />
      </geometry>
    </collision>
  </link>
  <joint
    name="ankleRoll_Right"
    type="revolute">
    <origin
      xyz="0 0 0"
      rpy="0 0 0" />
    <parent
      link="footRightY" />
    <child
      link="toe_right" />
    <axis
      xyz="1 0 0" />
    <limit effort="12.0" lower="-0.3491" upper="0.3491" velocity="20.0"/>
  </joint>
  <link
    name="waistRoll">
    <inertial>
      <origin
        xyz="0.001521 0.001495 0.039984"
        rpy="0 0 0" />
      <mass
        value="2.50" />
      <inertia
        ixx="0.006751"
        ixy="-0.000006"
        ixz="-0.000148"
        iyy="0.006755"
        iyz="0.000153"
        izz="0.002476" />
    </inertial>
    <visual>
      <origin
        xyz="0 0 0"
        rpy="0 0 0" />
      <geometry>
        <mesh
          filename="../meshes/yaocebai.obj" />
      </geometry>
      <material
        name="">
        <color
          rgba="0.752941176470588 0.752941176470588 0.752941176470588 1" />
      </material>
    </visual>
    <collision>
      <origin
        xyz="0.0 0.0 0.0"
        rpy="0 0 0" />
      <geometry>
        <mesh
          filename="../meshes/yaocebai.obj" />
      </geometry>
    </collision>
  </link>
  <joint
    name="waistRoll"
    type="revolute">
    <origin
      xyz="0 0 0.05023"
      rpy="0 0 0" />
    <parent
      link="pelvis" />
    <child
      link="waistRoll" />
    <axis
      xyz="1 0 0" />
    <limit effort="110" lower="-0.52" upper="0.52" velocity="8.0"/>
  </joint>
  <link
    name="waistPitch">
    <inertial>
      <origin
        xyz="0.0 -0.003646 0.029114"
        rpy="0 0 0" />
      <mass
        value="0.654478" />
      <inertia
        ixx="0.001170"
        ixy="0.0"
        ixz="0.0"
        iyy="0.000774"
        iyz="0.000039"
        izz="0.001207" />
    </inertial>
    <visual>
      <origin
        xyz="0 0 0"
        rpy="0 0 0" />
      <geometry>
        <mesh
          filename="../meshes/yaoqianbai.obj" />
      </geometry>
      <material
        name="">
        <color
          rgba="0.752941176470588 0.752941176470588 0.752941176470588 1" />
      </material>
    </visual>
    <collision>
      <origin
        xyz="0.0 0.0 0.0"
        rpy="0 0 0" />
      <geometry>
        <mesh
          filename="../meshes/yaoqianbai.obj" />
      </geometry>
    </collision>
  </link>
  <joint
    name="waistPitch"
    type="revolute">
    <origin
      xyz="0 0 0.08"
      rpy="0 0 0" />
    <parent
      link="waistRoll" />
    <child
      link="waistPitch" />
    <axis
      xyz="0 1 0" />
    <limit effort="110" lower="-0.78" upper="0.78" velocity="8.0"/>
  </joint>
  <link
    name="torso">
    <inertial>
      <origin
        xyz="0.005122 -0.000038 0.155343"
        rpy="0 0 0" />
      <mass
        value="10.0" />
      <inertia
        ixx="0.119619"
        ixy="-0.000021"
        ixz="-0.006001"
        iyy="0.099507"
        iyz="-0.000007"
        izz="0.063623" />
    </inertial>
    <visual>
      <origin
        xyz="0 0 0"
        rpy="0 0 0" />
      <geometry>
        <mesh
          filename="../meshes/xiongqiang.obj" />
      </geometry>
      <material
        name="">
        <color
          rgba="0.43921568627451 0.43921568627451 0.43921568627451 1" />
      </material>
    </visual>
     <collision>
      <origin
        xyz="0.0 0.0 0.0"
        rpy="0 0 0" />
      <geometry>
        <mesh
          filename="../meshes/xiongqiang.obj" />
      </geometry>
    </collision>
  </link>
  <joint
    name="waistYaw"
    type="revolute">
    <origin
      xyz="0 0 0.056115"
      rpy="0 0 0" />
    <parent
      link="waistPitch" />
    <child
      link="torso" />
    <axis
      xyz="0 0 1" />
    <limit effort="110" lower="-0.78" upper="0.78" velocity="8.0"/>
  </joint>
  <link
    name="shoulderBaseLeft">
    <inertial>
      <origin
        xyz="-0.001056 0.028803 0.000067"
        rpy="0 0 0" />
      <mass
        value="0.70" />
      <inertia
        ixx="0.000503"
        ixy="-0.000016"
        ixz="0.000001"
        iyy="0.000449"
        iyz="-0.000030"
        izz="0.000496" />
    </inertial>
    <visual>
      <origin
        xyz="0 0 0"
        rpy="0 0 0" />
      <geometry>
        <mesh
          filename="../meshes/zuobidizuo.obj" />
      </geometry>
      <material
        name="">
        <color
          rgba="0.752941176470588 0.752941176470588 0.752941176470588 1" />
      </material>
    </visual>
    <collision>
      <origin
        xyz="0.0 0.0 0.0"
        rpy="0 0 0" />
      <geometry>
        <mesh
          filename="../meshes/zuobidizuo.obj" />
      </geometry>
    </collision>
  </link>
  <joint
    name="shoulderBase_Left"
    type="fixed">
    <origin
      xyz="0.0020109 0.090449 0.23022"
      rpy="0.34907 0 0" />
    <parent
      link="torso" />
    <child
      link="shoulderBaseLeft" />
    <axis
      xyz="0 0 0" />
  </joint>
  <link
    name="shoulderPitchLeft">
    <inertial>
      <origin
        xyz="-0.00147856291704427 0.0312404594249897 0.000194586620615556"
        rpy="0 0 0" />
      <mass
        value="0.222453128267368" />
      <inertia
        ixx="0.000175"
        ixy="-0.000004"
        ixz="-0.000001"
        iyy="0.000328"
        iyz="0.000001"
        izz="0.000380" />
    </inertial>
    <visual>
      <origin
        xyz="0 0 0"
        rpy="0 0 0" />
      <geometry>
        <mesh
          filename="../meshes/zuo1.obj" />
      </geometry>
      <material
        name="">
        <color
          rgba="0.752941176470588 0.752941176470588 0.752941176470588 1" />
      </material>
    </visual>
     <collision>
      <origin
        xyz="0.0 0.0 0.0"
        rpy="0 0 0" />
      <geometry>
        <mesh
          filename="../meshes/zuo1.obj" />
      </geometry>
    </collision>
  </link>
  <joint
    name="shoulderPitch_Left"
    type="revolute">
    <origin
      xyz="-0.0020109 0.0717 -0.0011968"
      rpy="0 0 0" />
    <parent
      link="shoulderBaseLeft" />
    <child
      link="shoulderPitchLeft" />
    <axis
      xyz="0 1 0" />
    <limit effort="65.0" lower="-2.7" upper="1.0" velocity="8.0"/>
  </joint>
  <link
    name="shoulderRollLeft">
    <inertial>
      <origin
        xyz="-0.030453 0.010582 -0.014137"
        rpy="0 0 0" />
      <mass
        value="0.6" />
      <inertia
        ixx="0.000749"
        ixy="-0.000006"
        ixz="0.000013"
        iyy="0.000596"
        iyz="-0.000202"
        izz="0.000494" />
    </inertial>
    <visual>
      <origin
        xyz="0 0 0"
        rpy="0 0 0" />
      <geometry>
        <mesh
          filename="../meshes/zuo2.obj" />
      </geometry>
      <material
        name="">
        <color
          rgba="0.752941176470588 0.752941176470588 0.752941176470588 1" />
      </material>
    </visual>
    <collision>
      <origin
        xyz="0.0 0.0 0.0"
        rpy="0 0 0" />
      <geometry>
        <mesh
          filename="../meshes/zuo2.obj" />
      </geometry>
    </collision>
  </link>
  <joint
    name="shoulderRoll_Left"
    type="revolute">
    <origin
      xyz="0.0335 0.044 0"
      rpy="-0.34907 0 0" />
    <parent
      link="shoulderPitchLeft" />
    <child
      link="shoulderRollLeft" />
    <axis
      xyz="1 0 0" />
    <limit effort="65.0" lower="-0.3" upper="3.14" velocity="8.0"/> 
  </joint>
  <link
    name="shoulderYawLeft">
    <inertial>
      <origin
        xyz="-0.000951633773749558 -0.000636479898313447 -0.0979643093792619"
        rpy="0 0 0" />
      <mass
        value="0.853573592139701" />
      <inertia
        ixx="0.004701"
        ixy="-0.000001"
        ixz="0.000074"
        iyy="0.004533"
        iyz="0.000061"
        izz="0.000562" />
    </inertial>
    <visual>
      <origin
        xyz="0 0 0"
        rpy="0 0 0" />
      <geometry>
        <mesh
          filename="../meshes/zuo3.obj" />
      </geometry>
      <material
        name="">
        <color
          rgba="0.752941176470588 0.752941176470588 0.752941176470588 1" />
      </material>
    </visual>
    <collision>
      <origin
        xyz="0.0 0.0 0.0"
        rpy="0 0 0" />
      <geometry>
        <mesh
          filename="../meshes/zuo3.obj" />
      </geometry>
    </collision>
  </link>
  <joint
    name="shoulderYaw_Left"
    type="revolute">
    <origin
      xyz="-0.0335 0.034081 -0.059"
      rpy="0 0 0" />
    <parent
      link="shoulderRollLeft" />
    <child
      link="shoulderYawLeft" />
    <axis
      xyz="0 0 1" />
    <limit effort="65.0" lower="-1.6" upper="1.6" velocity="8.0"/>
  </joint>
  <link
    name="elbowLeft">
    <inertial>
      <origin
        xyz="-0.00410192417538807 0.0270255372034407 -0.0125478950788627"
        rpy="0 0 0" />
      <mass
        value="0.6" />
      <inertia
        ixx="0.000490"
        ixy="-0.000003"
        ixz="0.000074"
        iyy="0.000517"
        iyz="-0.000009"
        izz="0.000266" />
    </inertial>
    <visual>
      <origin
        xyz="0 0 0"
        rpy="0 0 0" />
      <geometry>
        <mesh
          filename="../meshes/zuo4.obj" />
      </geometry>
      <material
        name="">
        <color
          rgba="0.752941176470588 0.752941176470588 0.752941176470588 1" />
      </material>
    </visual>
    <collision>
      <origin
        xyz="0.0 0.0 0.0"
        rpy="0 0 0" />
      <geometry>
        <mesh
          filename="../meshes/zuo4.obj" />
      </geometry>
    </collision>
  </link>
  <joint
    name="elbow_Left"
    type="revolute">
    <origin
      xyz="0 -0.0285 -0.20365"
      rpy="0 0 0" />
    <parent
      link="shoulderYawLeft" />
    <child
      link="elbowLeft" />
    <axis
      xyz="0 1 0" />
    <limit effort="30.0" lower="-2.0" upper="0.0" velocity="8.0"/>
  </joint>
  <link
    name="wristYawLeft">
    <inertial>
      <origin
        xyz="0.000442314437274157 0.000143241533952454 -0.0845526326443413"
        rpy="0 0 0" />
      <mass
        value="1.100" />
      <inertia
        ixx="0.003522"
        ixy="0.0"
        ixz="0.000012"
        iyy="0.003513"
        iyz="0.000044"
        izz="0.000477" />
    </inertial>
    <visual>
      <origin
        xyz="0 0 0"
        rpy="0 0 0" />
      <geometry>
        <mesh
          filename="../meshes/zuo5.obj" />
      </geometry>
      <material
        name="">
        <color
          rgba="0.752941176470588 0.752941176470588 0.752941176470588 1" />
      </material>
    </visual>
    <collision>
      <origin
        xyz="0.0 0.0 0.0"
        rpy="0 0 0" />
      <geometry>
        <mesh
          filename="../meshes/zuo5.obj" />
      </geometry>
    </collision>
  </link>
  <joint
    name="wristYaw_Left"
    type="fixed">
    <origin
      xyz="-0.015 0.0285 -0.0709"
      rpy="0 0 0" />
    <parent
      link="elbowLeft" />
    <child
      link="wristYawLeft" />
    <axis
      xyz="0 0 1" />
  </joint>
  <link
    name="wristPitchLeft">
    <inertial>
      <origin
        xyz="0.00136233550856393 0.0 -0.000332353578728684"
        rpy="0 0 0" />
      <mass
        value="0.0487049922288782" />
      <inertia
        ixx="0.000018"
        ixy="0.0"
        ixz="0.0"
        iyy="0.000011"
        iyz="0.0"
        izz="0.000018" />
    </inertial>
    <visual>
      <origin
        xyz="0 0 0"
        rpy="0 0 0" />
      <geometry>
        <mesh
          filename="../meshes/zuo6.obj" />
      </geometry>
      <material
        name="">
        <color
          rgba="0.752941176470588 0.752941176470588 0.752941176470588 1" />
      </material>
    </visual>
    <collision>
      <origin
        xyz="0.0 0.0 0.0"
        rpy="0 0 0" />
      <geometry>
        <mesh
          filename="../meshes/zuo6.obj" />
      </geometry>
    </collision>
  </link>
  <joint
    name="wristPitch_Left"
    type="fixed">
    <origin
      xyz="0 0 -0.2035"
      rpy="0 0 0" />
    <parent
      link="wristYawLeft" />
    <child
      link="wristPitchLeft" />
    <axis
      xyz="0 1 0" />
  </joint>
  <link
    name="wristRollLeft">
    <inertial>
      <origin
        xyz="0.0205 0.0 -0.0430092538474871"
        rpy="0 0 0" />
      <mass
        value="0.0788585655835441" />
      <inertia
        ixx="0.000041"
        ixy="0.0"
        ixz="0.0"
        iyy="0.000053"
        iyz="0.0"
        izz="0.000027" />
    </inertial>
    <visual>
      <origin
        xyz="0 0 0"
        rpy="0 0 0" />
      <geometry>
        <mesh
          filename="../meshes/zuo7.obj" />
      </geometry>
      <material
        name="">
        <color
          rgba="0.752941176470588 0.752941176470588 0.752941176470588 1" />
      </material>
    </visual>
    <collision>
      <origin
        xyz="0.0 0.0 0.0"
        rpy="0 0 0" />
      <geometry>
        <mesh
          filename="../meshes/zuo7.obj" />
      </geometry>
    </collision>
  </link>
  <joint
    name="wristRoll_Left"
    type="fixed">
    <origin
      xyz="-0.0205 0 0"
      rpy="0 0 0" />
    <parent
      link="wristPitchLeft" />
    <child
      link="wristRollLeft" />
    <axis
      xyz="1 0 0" />
  </joint>
  <link
    name="shoulderBaseRight">
    <inertial>
      <origin
        xyz="-0.001056 -0.028803 0.000067"
        rpy="0 0 0" />
      <mass
        value="0.70" />
      <inertia
        ixx="0.000503"
        ixy="0.000016"
        ixz="0.000001"
        iyy="0.000449"
        iyz="0.000030"
        izz="0.000496" />
    </inertial>
    <visual>
      <origin
        xyz="0 0 0"
        rpy="0 0 0" />
      <geometry>
        <mesh
          filename="../meshes/youbidizuo.obj" />
      </geometry>
      <material
        name="">
        <color
          rgba="0.752941176470588 0.752941176470588 0.752941176470588 1" />
      </material>
    </visual>
    <collision>
      <origin
        xyz="0.0 0.0 0.0"
        rpy="0 0 0" />
      <geometry>
        <mesh
          filename="../meshes/youbidizuo.obj" />
      </geometry>
    </collision>
  </link>
  <joint
    name="shoulderBase_Right"
    type="fixed">
    <origin
      xyz="0.0020109 -0.090449 0.23022"
      rpy="-0.34907 0 0" />
    <parent
      link="torso" />
    <child
      link="shoulderBaseRight" />
    <axis
      xyz="0 0 0" />
  </joint>
  <link
    name="shoulderPitchRight">
    <inertial>
      <origin
        xyz="-0.00147856291704427 -0.0312404594249897 0.000194586620615556"
        rpy="0 0 0" />
      <mass
        value="0.222453128267368" />
      <inertia
        ixx="0.000175"
        ixy="0.000004"
        ixz="-0.000001"
        iyy="0.000328"
        iyz="-0.000001"
        izz="0.000380" />
    </inertial>
    <visual>
      <origin
        xyz="0 0 0"
        rpy="0 0 0" />
      <geometry>
        <mesh
          filename="../meshes/you1.obj" />
      </geometry>
      <material
        name="">
        <color
          rgba="0.752941176470588 0.752941176470588 0.752941176470588 1" />
      </material>
    </visual>
    <collision>
      <origin
        xyz="0.0 0.0 0.0"
        rpy="0 0 0" />
      <geometry>
        <mesh
          filename="../meshes/you1.obj" />
      </geometry>
    </collision>
  </link>
  <joint
    name="shoulderPitch_Right"
    type="revolute">
    <origin
      xyz="-0.0020109 -0.0717 -0.0011968"
      rpy="0 0 0" />
    <parent
      link="shoulderBaseRight" />
    <child
      link="shoulderPitchRight" />
    <axis
      xyz="0 1 0" />
    <limit effort="65.0" lower="-2.7" upper="1.1" velocity="8.0"/>
  </joint>
  <link
    name="shoulderRollRight">
    <inertial>
      <origin
        xyz="-0.030453 -0.010582 -0.014137"
        rpy="0 0 0" />
      <mass
        value="0.6" />
      <inertia
        ixx="0.000749"
        ixy="0.000006"
        ixz="0.000013"
        iyy="0.000596"
        iyz="0.000202"
        izz="0.000494" />
    </inertial>
    <visual>
      <origin
        xyz="0 0 0"
        rpy="0 0 0" />
      <geometry>
        <mesh
          filename="../meshes/you2.obj" />
      </geometry>
      <material
        name="">
        <color
          rgba="0.752941176470588 0.752941176470588 0.752941176470588 1" />
      </material>
    </visual>
    <collision>
      <origin
        xyz="0.0 0.0 0.0"
        rpy="0 0 0" />
      <geometry>
        <mesh
          filename="../meshes/you2.obj" />
      </geometry>
    </collision>
  </link>
  <joint
    name="shoulderRoll_Right"
    type="revolute">
    <origin
      xyz="0.0335 -0.044 0"
      rpy="0.34907 0 0" />
    <parent
      link="shoulderPitchRight" />
    <child
      link="shoulderRollRight" />
    <axis
      xyz="1 0 0" />
    <limit effort="65.0" lower="-3.14" upper="0.3" velocity="8.0"/>
  </joint>
  <link
    name="shoulderYawRight">
    <inertial>
      <origin
        xyz="-0.000951633773749558 0.000636479898313447 -0.0979643093792619"
        rpy="0 0 0" />
      <mass
        value="0.853573592139701" />
      <inertia
        ixx="0.004701"
        ixy="0.000001"
        ixz="0.000074"
        iyy="0.004533"
        iyz="-0.000061"
        izz="0.000562" />
    </inertial>
    <visual>
      <origin
        xyz="0 0 0"
        rpy="0 0 0" />
      <geometry>
        <mesh
          filename="../meshes/you3.obj" />
      </geometry>
      <material
        name="">
        <color
          rgba="0.752941176470588 0.752941176470588 0.752941176470588 1" />
      </material>
    </visual>
    <collision>
      <origin
        xyz="0.0 0.0 0.0"
        rpy="0 0 0" />
      <geometry>
        <mesh
          filename="../meshes/you3.obj" />
      </geometry>
    </collision>
  </link>
  <joint
    name="shoulderYaw_Right"
    type="revolute">
    <origin
      xyz="-0.0335 -0.034081 -0.059"
      rpy="0 0 0" />
    <parent
      link="shoulderRollRight" />
    <child
      link="shoulderYawRight" />
    <axis
      xyz="0 0 1" />
    <limit effort="65.0" lower="-1.6" upper="1.6" velocity="8.0"/>
  </joint>
  <link
    name="elbowRight">
    <inertial>
      <origin
        xyz="-0.00410192417538807 -0.0270255372034407 -0.0125478950788627"
        rpy="0 0 0" />
      <mass
        value="0.6" />
      <inertia
        ixx="0.000490"
        ixy="0.000003"
        ixz="0.000074"
        iyy="0.000517"
        iyz="0.000009"
        izz="0.000266" />
    </inertial>
    <visual>
      <origin
        xyz="0 0 0"
        rpy="0 0 0" />
      <geometry>
        <mesh
          filename="../meshes/you4.obj" />
      </geometry>
      <material
        name="">
        <color
          rgba="0.752941176470588 0.752941176470588 0.752941176470588 1" />
      </material>
    </visual>
    <collision>
      <origin
        xyz="0.0 0.0 0.0"
        rpy="0 0 0" />
      <geometry>
        <mesh
          filename="../meshes/you4.obj" />
      </geometry>
    </collision>
  </link>
  <joint
    name="elbow_Right"
    type="revolute">
    <origin
      xyz="0 0.0285 -0.20365"
      rpy="0 0 0" />
    <parent
      link="shoulderYawRight" />
    <child
      link="elbowRight" />
    <axis
      xyz="0 1 0" />
    <limit effort="30.0" lower="-2.0" upper="0.0" velocity="8.0"/>
  </joint>
  <link
    name="wristYawRight">
    <inertial>
      <origin
        xyz="0.000442314437274157 -0.000143241533952454 -0.0845526326443413"
        rpy="0 0 0" />
      <mass
        value="1.100" />
      <inertia
        ixx="0.003522"
        ixy="0.0"
        ixz="0.000012"
        iyy="0.003513"
        iyz="-0.000044"
        izz="0.000477" />
    </inertial>
    <visual>
      <origin
        xyz="0 0 0"
        rpy="0 0 0" />
      <geometry>
        <mesh
          filename="../meshes/you5.obj" />
      </geometry>
      <material
        name="">
        <color
          rgba="0.752941176470588 0.752941176470588 0.752941176470588 1" />
      </material>
    </visual>
    <collision>
      <origin
        xyz="0.0 0.0 0.0"
        rpy="0 0 0" />
      <geometry>
        <mesh
          filename="../meshes/you5.obj" />
      </geometry>
    </collision>
  </link>
  <joint
    name="wristYaw_Right"
    type="fixed">
    <origin
      xyz="-0.015 -0.0285 -0.0709"
      rpy="0 0 0" />
    <parent
      link="elbowRight" />
    <child
      link="wristYawRight" />
    <axis
      xyz="0 0 1" />
  </joint>
  <link
    name="wristPitchRight">
    <inertial>
      <origin
        xyz="0.00136233550856393 0.0 -0.000332353578728684"
        rpy="0 0 0" />
      <mass
        value="0.0487049922288782" />
      <inertia
        ixx="0.000018"
        ixy="0.0"
        ixz="0.0"
        iyy="0.000011"
        iyz="0.0"
        izz="0.000018" />
    </inertial>
    <visual>
      <origin
        xyz="0 0 0"
        rpy="0 0 0" />
      <geometry>
        <mesh
          filename="../meshes/you6.obj" />
      </geometry>
      <material
        name="">
        <color
          rgba="0.752941176470588 0.752941176470588 0.752941176470588 1" />
      </material>
    </visual>
    <collision>
      <origin
        xyz="0.0 0.0 0.0"
        rpy="0 0 0" />
      <geometry>
        <mesh
          filename="../meshes/you6.obj" />
      </geometry>
    </collision>
  </link>
  <joint
    name="wristPitch_Right"
    type="fixed">
    <origin
      xyz="0 0 -0.2035"
      rpy="0 0 0" />
    <parent
      link="wristYawRight" />
    <child
      link="wristPitchRight" />
    <axis
      xyz="0 1 0" />
  </joint>
  <link
    name="wristRollRight">
    <inertial>
      <origin
        xyz="0.0205 0.0 -0.0430092538474871"
        rpy="0 0 0" />
      <mass
        value="0.0788585655835441" />
      <inertia
        ixx="0.000041"
        ixy="0.0"
        ixz="0.0"
        iyy="0.000053"
        iyz="0.0"
        izz="0.000027" />
    </inertial>
    <visual>
      <origin
        xyz="0.041 0 0"
        rpy="0 0 0" />
      <geometry>
        <mesh
          filename="../meshes/you7.obj" />
      </geometry>
      <material
        name="">
        <color
          rgba="0.752941176470588 0.752941176470588 0.752941176470588 1" />
      </material>
    </visual>
    <collision>
      <origin
        xyz="0.0 0.0 0.0"
        rpy="0 0 0" />
      <geometry>
        <mesh
          filename="../meshes/you7.obj" />
      </geometry>
    </collision>
  </link>
  <joint
    name="wristRoll_Right"
    type="fixed">
    <origin
      xyz="-0.0205 0 0"
      rpy="0 0 0" />
    <parent
      link="wristPitchRight" />
    <child
      link="wristRollRight" />
    <axis
      xyz="1 0 0" />
  </joint>
  <link
    name="headBase">
    <inertial>
      <origin
        xyz="0.0013919435755768 -1.3657835903023E-13 0.0255558265968819"
        rpy="0 0 0" />
      <mass
        value="0.246617063216893" />
      <inertia
        ixx="7.79142910881016E-05"
        ixy="3.31030574459433E-16"
        ixz="6.42983116624786E-06"
        iyy="8.2711824376371E-05"
        iyz="-4.8127081543934E-16"
        izz="8.06939168742559E-05" />
    </inertial>
    <visual>
      <origin
        xyz="0 0 0"
        rpy="0 0 0" />
      <geometry>
        <mesh
          filename="../meshes/toujizuo.obj" />
      </geometry>
      <material
        name="">
        <color
          rgba="0.752941176470588 0.752941176470588 0.752941176470588 1" />
      </material>
    </visual>
    <collision>
      <origin
        xyz="0.0 0.0 0.0"
        rpy="0 0 0" />
      <geometry>
        <mesh
          filename="../meshes/toujizuo.obj" />
      </geometry>
    </collision>
  </link>
  <joint
    name="headBase"
    type="fixed">
    <origin
      xyz="-0.013 0 0.24889"
      rpy="0 0 0" />
    <parent
      link="torso" />
    <child
      link="headBase" />
    <axis
      xyz="0 0 0" />
  </joint>
  <link
    name="headYaw">
    <inertial>
      <origin
        xyz="0.00108603797509827 0.000630868200051806 0.0297220441021733"
        rpy="0 0 0" />
      <mass
        value="0.296228098050558" />
      <inertia
        ixx="0.000107209290629429"
        ixy="1.53198856129565E-08"
        ixz="2.43697965569866E-07"
        iyy="0.000115134776830452"
        iyz="-5.42702247464397E-06"
        izz="9.5589582444944E-05" />
    </inertial>
    <visual>
      <origin
        xyz="0 0 0"
        rpy="0 0 0" />
      <geometry>
        <mesh
          filename="../meshes/tou1.obj" />
      </geometry>
      <material
        name="">
        <color
          rgba="0.752941176470588 0.752941176470588 0.752941176470588 1" />
      </material>
    </visual>
    <collision>
      <origin
        xyz="0.0 0.0 0.0"
        rpy="0 0 0" />
      <geometry>
        <mesh
          filename="../meshes/tou1.obj" />
      </geometry>
    </collision>
  </link>
  <joint
    name="headYaw"
    type="fixed">
    <origin
      xyz="0 0 0.0524"
      rpy="0 0 0" />
    <parent
      link="headBase" />
    <child
      link="headYaw" />
    <axis
      xyz="0 0 1" />
  </joint>
  <link
    name="headPitch">
    <inertial>
      <origin
        xyz="0.00461584985679341 -0.0224894202201687 0.108037241015781"
        rpy="0 0 0" />
      <mass
        value="0.37936446393091" />
      <inertia
        ixx="0.000159798587063736"
        ixy="-1.81203511016259E-08"
        ixz="-1.56709597128011E-05"
        iyy="0.000143098819251937"
        iyz="-3.29193916344999E-08"
        izz="0.000118285323615158" />
    </inertial>
    <visual>
      <origin
        xyz="0 0 0"
        rpy="0 0 0" />
      <geometry>
        <mesh
          filename="../meshes/tou2.obj" />
      </geometry>
      <material
        name="">
        <color
          rgba="0.752941176470588 0.752941176470588 0.752941176470588 1" />
      </material>
    </visual>
    <collision>
      <origin
        xyz="0.0 0.0 0.0"
        rpy="0 0 0" />
      <geometry>
        <mesh
          filename="../meshes/tou2.obj" />
      </geometry>
    </collision>
  </link>
  <joint
    name="headPitch"
    type="fixed">
    <origin
      xyz="-1.2524E-05 0.0234 0.032452"
      rpy="0 0 0" />
    <parent
      link="headYaw" />
    <child
      link="headPitch" />
    <axis
      xyz="0 1 0" />
  </joint>
  <link
    name="headRoll">
    <inertial>
      <origin
        xyz="-0.0123138121380026 1.08114225684127E-05 0.0444768820754399"
        rpy="0 0 0" />
      <mass
        value="1.13520682485993" />
      <inertia
        ixx="0.00415298360750852"
        ixy="6.88759309292714E-07"
        ixz="0.000169085818222547"
        iyy="0.0048334102764911"
        iyz="-1.04604506109954E-06"
        izz="0.0045455849776474" />
    </inertial>
    <visual>
      <origin
        xyz="0 0 0"
        rpy="0 0 0" />
      <geometry>
        <mesh
          filename="../meshes/tou3.obj" />
      </geometry>
      <material
        name="">
        <color
          rgba="0.898039215686275 0.917647058823529 0.929411764705882 1" />
      </material>
    </visual>
    <collision>
      <origin
        xyz="0.0 0.0 0.0"
        rpy="0 0 0" />
      <geometry>
        <mesh
          filename="../meshes/tou3.obj" />
      </geometry>
    </collision>
  </link>
  <joint
    name="headRoll"
    type="fixed">
    <origin
      xyz="0.026742 -0.0234 0.1286"
      rpy="0 0 0" />
    <parent
      link="headPitch" />
    <child
      link="headRoll" />
    <axis
      xyz="1 0 0" />
  </joint>
</robot>